Workbook

Sheet Customer_churn_data
A1: CustID | B1: Customer Name | C1: Gender | D1: Age | E1: age group | F1: City | G1: Contract Type | H1: Tenure (Months) | I1: Tenure Bucket | J1: Monthly Charges (₹) | K1: Total Charges (₹) | L1: Internet Service | M1: Signup Date | N1: Churn | O1: Churn_Flag | P1: Age_Imputed | Q1: Tenure_Imputed | R1: Monthly_Imputed | S1: Total_Imputed | T1: Needs_Review | U1: Totalkey
A2: C1001 | B2: Rahul Agarwal | C2: Male | D2: 35 | E2: =IF(D2<=25,"18-25",IF(D2<=35,"26-35",IF(D2<=45,"36-45",IF(D2<=60,"46-60","60+")))) -> 26-35 | F2: Hyderabad | G2: Month-to-month | H2: 22 | I2: =IF(H2="","Unknown",IF(H2<=6,"0-6 months",IF(H2<=12,"7-12 months",IF(H2<=24,"13-24 months",IF(H2<=48,"25-48 months","49+ months"))))) -> 13-24 months | J2: 1149 | K2: 25278 | L2: Fiber | M2: 45267 | N2: No | O2: =IF(N2="Yes",1,IF(N2="No",0,"")) -> 0 | P2: No | Q2: No | R2: No | S2: No | T2: No | U2: =IF(K2="","",K2+ROW()/1000000) -> 25278
A3: C1002 | B3: Vikram Mehta | C3: Male | D3: 32 | E3: =IF(D3<=25,"18-25",IF(D3<=35,"26-35",IF(D3<=45,"36-45",IF(D3<=60,"46-60","60+")))) -> 26-35 | F3: Jaipur | G3: One year | H3: 35 | I3: =IF(H3="","Unknown",IF(H3<=6,"0-6 months",IF(H3<=12,"7-12 months",IF(H3<=24,"13-24 months",IF(H3<=48,"25-48 months","49+ months"))))) -> 25-48 months | J3: 999 | K3: 34965 | L3: Fiber | M3: 44853 | N3: No | O3: =IF(N3="Yes",1,IF(N3="No",0,"")) -> 0 | P3: No | Q3: No | R3: No | S3: No | T3: No | U3: =IF(K3="","",K3+ROW()/1000000) -> 34965
A4: C1003 | B4: Arjun Pandey | C4: Male | D4: 47 | E4: =IF(D4<=25,"18-25",IF(D4<=35,"26-35",IF(D4<=45,"36-45",IF(D4<=60,"46-60","60+")))) -> 46-60 | F4: Pune | G4: Month-to-month | H4: 11 | I4: =IF(H4="","Unknown",IF(H4<=6,"0-6 months",IF(H4<=12,"7-12 months",IF(H4<=24,"13-24 months",IF(H4<=48,"25-48 months","49+ months"))))) -> 7-12 months | J4: 599 | K4: 6589 | L4: DSL | M4: 45571 | N4: Yes | O4: =IF(N4="Yes",1,IF(N4="No",0,"")) -> 1 | P4: Yes | Q4: No | R4: No | S4: No | T4: No | U4: =IF(K4="","",K4+ROW()/1000000) -> 6589
A5: C1004 | B5: Riya Malhotra | C5: Female | D5: 69 | E5: =IF(D5<=25,"18-25",IF(D5<=35,"26-35",IF(D5<=45,"36-45",IF(D5<=60,"46-60","60+")))) -> 60+ | F5: Delhi | G5: One year | H5: 25 | I5: =IF(H5="","Unknown",IF(H5<=6,"0-6 months",IF(H5<=12,"7-12 months",IF(H5<=24,"13-24 months",IF(H5<=48,"25-48 months","49+ months"))))) -> 25-48 months | J5: 1149 | K5: 28725 | L5: Fiber | M5: 45159 | N5: Unknown | O5: =IF(N5="Yes",1,IF(N5="No",0,"")) | P5: No | Q5: No | R5: No | S5: No | T5: Churn unknown | U5: =IF(K5="","",K5+ROW()/1000000) -> 28725
A6: C1005 | B6: Tanvi Mehta | C6: Female | D6: 63 | E6: =IF(D6<=25,"18-25",IF(D6<=35,"26-35",IF(D6<=45,"36-45",IF(D6<=60,"46-60","60+")))) -> 60+ | F6: Mumbai | G6: Month-to-month | H6: 10 | I6: =IF(H6="","Unknown",IF(H6<=6,"0-6 months",IF(H6<=12,"7-12 months",IF(H6<=24,"13-24 months",IF(H6<=48,"25-48 months","49+ months"))))) -> 7-12 months | J6: 599 | K6: 5990 | L6: DSL | M6: 45616 | N6: No | O6: =IF(N6="Yes",1,IF(N6="No",0,"")) -> 0 | P6: No | Q6: No | R6: No | S6: No | T6: No | U6: =IF(K6="","",K6+ROW()/1000000) -> 5990
A7: C1006 | B7: Shreya Chopra | C7: Female | D7: 71 | E7: =IF(D7<=25,"18-25",IF(D7<=35,"26-35",IF(D7<=45,"36-45",IF(D7<=60,"46-60","60+")))) -> 60+ | F7: Pune | G7: Month-to-month | H7: 22 | I7: =IF(H7="","Unknown",IF(H7<=6,"0-6 months",IF(H7<=12,"7-12 months",IF(H7<=24,"13-24 months",IF(H7<=48,"25-48 months","49+ months"))))) -> 13-24 months | J7: 1199 | K7: 26378 | L7: Fiber | M7: 45263 | N7: No | O7: =IF(N7="Yes",1,IF(N7="No",0,"")) -> 0 | P7: No | Q7: No | R7: No | S7: No | T7: No | U7: =IF(K7="","",K7+ROW()/1000000) -> 26378
A8: C1007 | B8: Arjun Kapoor | C8: Male | D8: 42 | E8: =IF(D8<=25,"18-25",IF(D8<=35,"26-35",IF(D8<=45,"36-45",IF(D8<=60,"46-60","60+")))) -> 36-45 | F8: Chennai | G8: Two year | H8: 72 | I8: =IF(H8="","Unknown",IF(H8<=6,"0-6 months",IF(H8<=12,"7-12 months",IF(H8<=24,"13-24 months",IF(H8<=48,"25-48 months","49+ months"))))) -> 49+ months | J8: 1199 | K8: 86328 | L8: Fiber | M8: 43744 | N8: No | O8: =IF(N8="Yes",1,IF(N8="No",0,"")) -> 0 | P8: No | Q8: No | R8: No | S8: No | T8: No | U8: =IF(K8="","",K8+ROW()/1000000) -> 86328
A9: C1008 | B9: Manish Verma | C9: Male | D9: 69 | E9: =IF(D9<=25,"18-25",IF(D9<=35,"26-35",IF(D9<=45,"36-45",IF(D9<=60,"46-60","60+")))) -> 60+ | F9: Pune | G9: Month-to-month | H9: 19 | I9: =IF(H9="","Unknown",IF(H9<=6,"0-6 months",IF(H9<=12,"7-12 months",IF(H9<=24,"13-24 months",IF(H9<=48,"25-48 months","49+ months"))))) -> 13-24 months | J9: 849 | K9: 16131 | L9: DSL | M9: 45346 | N9: No | O9: =IF(N9="Yes",1,IF(N9="No",0,"")) -> 0 | P9: No | Q9: No | R9: No | S9: No | T9: No | U9: =IF(K9="","",K9+ROW()/1000000) -> 16131
A10: C1009 | B10: Pooja Malhotra | C10: Female | D10: 26 | E10: =IF(D10<=25,"18-25",IF(D10<=35,"26-35",IF(D10<=45,"36-45",IF(D10<=60,"46-60","60+")))) -> 26-35 | F10: Hyderabad | G10: One year | H10: 38 | I10: =IF(H10="","Unknown",IF(H10<=6,"0-6 months",IF(H10<=12,"7-12 months",IF(H10<=24,"13-24 months",IF(H10<=48,"25-48 months","49+ months"))))) -> 25-48 months | J10: 1149 | K10: 43662 | L10: Fiber | M10: 44784 | N10: No | O10: =IF(N10="Yes",1,IF(N10="No",0,"")) -> 0 | P10: No | Q10: No | R10: No | S10: Yes | T10: No | U10: =IF(K10="","",K10+ROW()/1000000) -> 43662
A11: C1010 | B11: Neha Verma | C11: Female | D11: 73 | E11: =IF(D11<=25,"18-25",IF(D11<=35,"26-35",IF(D11<=45,"36-45",IF(D11<=60,"46-60","60+")))) -> 60+ | F11: Mumbai | G11: Month-to-month | H11: 22 | I11: =IF(H11="","Unknown",IF(H11<=6,"0-6 months",IF(H11<=12,"7-12 months",IF(H11<=24,"13-24 months",IF(H11<=48,"25-48 months","49+ months"))))) -> 13-24 months | J11: 749 | K11: 16478 | L11: DSL | N11: Yes | O11: =IF(N11="Yes",1,IF(N11="No",0,"")) -> 1 | P11: No | Q11: No | R11: No | S11: No | T11: Date missing | U11: =IF(K11="","",K11+ROW()/1000000) -> 16478
A12: C1011 | B12: Payal Malhotra | C12: Female | D12: 53 | E12: =IF(D12<=25,"18-25",IF(D12<=35,"26-35",IF(D12<=45,"36-45",IF(D12<=60,"46-60","60+")))) -> 46-60 | F12: Chandigarh | G12: Two year | H12: 15 | I12: =IF(H12="","Unknown",IF(H12<=6,"0-6 months",IF(H12<=12,"7-12 months",IF(H12<=24,"13-24 months",IF(H12<=48,"25-48 months","49+ months"))))) -> 13-24 months | J12: 1149 | K12: 17235 | L12: Fiber | M12: 45468 | N12: No | O12: =IF(N12="Yes",1,IF(N12="No",0,"")) -> 0 | P12: No | Q12: No | R12: No | S12: No | T12: No | U12: =IF(K12="","",K12+ROW()/1000000) -> 17235
A13: C1012 | B13: Harsh Tiwari | C13: Male | D13: 28 | E13: =IF(D13<=25,"18-25",IF(D13<=35,"26-35",IF(D13<=45,"36-45",IF(D13<=60,"46-60","60+")))) -> 26-35 | F13: Ahmedabad | G13: Month-to-month | H13: 24 | I13: =IF(H13="","Unknown",IF(H13<=6,"0-6 months",IF(H13<=12,"7-12 months",IF(H13<=24,"13-24 months",IF(H13<=48,"25-48 months","49+ months"))))) -> 13-24 months | J13: 1149 | K13: 27576 | L13: Fiber | M13: 45205 | N13: No | O13: =IF(N13="Yes",1,IF(N13="No",0,"")) -> 0 | P13: No | Q13: No | R13: No | S13: No | T13: No | U13: =IF(K13="","",K13+ROW()/1000000) -> 27576
A14: C1013 | B14: Payal Yadav | C14: Unknown | D14: 30 | E14: =IF(D14<=25,"18-25",IF(D14<=35,"26-35",IF(D14<=45,"36-45",IF(D14<=60,"46-60","60+")))) -> 26-35 | F14: Bangalore | G14: Month-to-month | H14: 17 | I14: =IF(H14="","Unknown",IF(H14<=6,"0-6 months",IF(H14<=12,"7-12 months",IF(H14<=24,"13-24 months",IF(H14<=48,"25-48 months","49+ months"))))) -> 13-24 months | J14: 599 | K14: 10183 | L14: DSL | M14: 45415 | N14: No | O14: =IF(N14="Yes",1,IF(N14="No",0,"")) -> 0 | P14: No | Q14: No | R14: No | S14: No | T14: No | U14: =IF(K14="","",K14+ROW()/1000000) -> 10183
A15: C1014 | B15: Aditi Nair | C15: Female | D15: 21 | E15: =IF(D15<=25,"18-25",IF(D15<=35,"26-35",IF(D15<=45,"36-45",IF(D15<=60,"46-60","60+")))) -> 18-25 | F15: Hyderabad | G15: Two year | H15: 11 | I15: =IF(H15="","Unknown",IF(H15<=6,"0-6 months",IF(H15<=12,"7-12 months",IF(H15<=24,"13-24 months",IF(H15<=48,"25-48 months","49+ months"))))) -> 7-12 months | J15: 349 | K15: 3839 | L15: No Internet | M15: 45581 | N15: No | O15: =IF(N15="Yes",1,IF(N15="No",0,"")) -> 0 | P15: No | Q15: No | R15: No | S15: No | T15: No | U15: =IF(K15="","",K15+ROW()/1000000) -> 3839
A16: C1015 | B16: Rohit Saxena | C16: Unknown | D16: 48 | E16: =IF(D16<=25,"18-25",IF(D16<=35,"26-35",IF(D16<=45,"36-45",IF(D16<=60,"46-60","60+")))) -> 46-60 | F16: Jaipur | G16: Month-to-month | H16: 20 | I16: =IF(H16="","Unknown",IF(H16<=6,"0-6 months",IF(H16<=12,"7-12 months",IF(H16<=24,"13-24 months",IF(H16<=48,"25-48 months","49+ months"))))) -> 13-24 months | J16: 999 | K16: 19980 | L16: Fiber | M16: 45306 | N16: No | O16: =IF(N16="Yes",1,IF(N16="No",0,"")) -> 0 | P16: No | Q16: No | R16: No | S16: No | T16: No | U16: =IF(K16="","",K16+ROW()/1000000) -> 19980
A17: C1016 | B17: Harsh Rao | C17: Male | D17: 60 | E17: =IF(D17<=25,"18-25",IF(D17<=35,"26-35",IF(D17<=45,"36-45",IF(D17<=60,"46-60","60+")))) -> 46-60 | F17: Indore | G17: Month-to-month | I17: =IF(H17="","Unknown",IF(H17<=6,"0-6 months",IF(H17<=12,"7-12 months",IF(H17<=24,"13-24 months",IF(H17<=48,"25-48 months","49+ months"))))) -> Unknown | K17: 5985 | L17: No Internet | M17: 45478 | N17: Yes | O17: =IF(N17="Yes",1,IF(N17="No",0,"")) -> 1 | P17: No | Q17: No | R17: No | S17: No | T17: Monthly missing; Tenure missing | U17: =IF(K17="","",K17+ROW()/1000000) -> 5985
A18: C1017 | B18: Rajesh Nair | C18: Male | D18: 18 | E18: =IF(D18<=25,"18-25",IF(D18<=35,"26-35",IF(D18<=45,"36-45",IF(D18<=60,"46-60","60+")))) -> 18-25 | F18: Mumbai | G18: One year | H18: 5 | I18: =IF(H18="","Unknown",IF(H18<=6,"0-6 months",IF(H18<=12,"7-12 months",IF(H18<=24,"13-24 months",IF(H18<=48,"25-48 months","49+ months"))))) -> 0-6 months | J18: 599 | K18: 2995 | L18: DSL | M18: 45771 | N18: Yes | O18: =IF(N18="Yes",1,IF(N18="No",0,"")) -> 1 | P18: No | Q18: No | R18: No | S18: No | T18: No | U18: =IF(K18="","",K18+ROW()/1000000) -> 2995
A19: C1018 | B19: Komal Mehta | C19: Female | D19: 52 | E19: =IF(D19<=25,"18-25",IF(D19<=35,"26-35",IF(D19<=45,"36-45",IF(D19<=60,"46-60","60+")))) -> 46-60 | F19: Bangalore | G19: One year | H19: 37 | I19: =IF(H19="","Unknown",IF(H19<=6,"0-6 months",IF(H19<=12,"7-12 months",IF(H19<=24,"13-24 months",IF(H19<=48,"25-48 months","49+ months"))))) -> 25-48 months | J19: 499 | K19: 18463 | L19: No Internet | M19: 44812 | N19: No | O19: =IF(N19="Yes",1,IF(N19="No",0,"")) -> 0 | P19: No | Q19: No | R19: No | S19: No | T19: No | U19: =IF(K19="","",K19+ROW()/1000000) -> 18463
A20: C1019 | B20: Karan Saxena | C20: Male | D20: 45 | E20: =IF(D20<=25,"18-25",IF(D20<=35,"26-35",IF(D20<=45,"36-45",IF(D20<=60,"46-60","60+")))) -> 36-45 | F20: Pune | G20: Month-to-month | H20: 24 | I20: =IF(H20="","Unknown",IF(H20<=6,"0-6 months",IF(H20<=12,"7-12 months",IF(H20<=24,"13-24 months",IF(H20<=48,"25-48 months","49+ months"))))) -> 13-24 months | J20: 1199 | K20: 28776 | L20: Fiber | M20: 45185 | N20: Yes | O20: =IF(N20="Yes",1,IF(N20="No",0,"")) -> 1 | P20: No | Q20: No | R20: No | S20: No | T20: No | U20: =IF(K20="","",K20+ROW()/1000000) -> 28776
A21: C1020 | B21: Anjali Nair | C21: Female | D21: 30 | E21: =IF(D21<=25,"18-25",IF(D21<=35,"26-35",IF(D21<=45,"36-45",IF(D21<=60,"46-60","60+")))) -> 26-35 | F21: Hyderabad | G21: Month-to-month | H21: 6 | I21: =IF(H21="","Unknown",IF(H21<=6,"0-6 months",IF(H21<=12,"7-12 months",IF(H21<=24,"13-24 months",IF(H21<=48,"25-48 months","49+ months"))))) -> 0-6 months | J21: 699 | K21: 4194 | L21: DSL | M21: 45746 | N21: No | O21: =IF(N21="Yes",1,IF(N21="No",0,"")) -> 0 | P21: No | Q21: No | R21: No | S21: Yes | T21: No | U21: =IF(K21="","",K21+ROW()/1000000) -> 4194
A22: C1021 | B22: Sonal Reddy | C22: Female | D22: 21 | E22: =IF(D22<=25,"18-25",IF(D22<=35,"26-35",IF(D22<=45,"36-45",IF(D22<=60,"46-60","60+")))) -> 18-25 | F22: Indore | G22: Two year | H22: 12 | I22: =IF(H22="","Unknown",IF(H22<=6,"0-6 months",IF(H22<=12,"7-12 months",IF(H22<=24,"13-24 months",IF(H22<=48,"25-48 months","49+ months"))))) -> 7-12 months | J22: 399 | K22: 4788 | L22: No Internet | M22: 45553 | N22: No | O22: =IF(N22="Yes",1,IF(N22="No",0,"")) -> 0 | P22: No | Q22: No | R22: No | S22: Yes | T22: No | U22: =IF(K22="","",K22+ROW()/1000000) -> 4788
A23: C1022 | B23: Deepika Rao | C23: Female | D23: 75 | E23: =IF(D23<=25,"18-25",IF(D23<=35,"26-35",IF(D23<=45,"36-45",IF(D23<=60,"46-60","60+")))) -> 60+ | F23: Delhi | G23: Month-to-month | H23: 13 | I23: =IF(H23="","Unknown",IF(H23<=6,"0-6 months",IF(H23<=12,"7-12 months",IF(H23<=24,"13-24 months",IF(H23<=48,"25-48 months","49+ months"))))) -> 13-24 months | J23: 699 | K23: 9087 | L23: DSL | M23: 45516 | N23: Yes | O23: =IF(N23="Yes",1,IF(N23="No",0,"")) -> 1 | P23: No | Q23: No | R23: No | S23: No | T23: No | U23: =IF(K23="","",K23+ROW()/1000000) -> 9087
A24: C1023 | B24: Pooja Mehta | C24: Female | D24: 36 | E24: =IF(D24<=25,"18-25",IF(D24<=35,"26-35",IF(D24<=45,"36-45",IF(D24<=60,"46-60","60+")))) -> 36-45 | F24: Hyderabad | G24: Two year | H24: 70 | I24: =IF(H24="","Unknown",IF(H24<=6,"0-6 months",IF(H24<=12,"7-12 months",IF(H24<=24,"13-24 months",IF(H24<=48,"25-48 months","49+ months"))))) -> 49+ months | J24: 1199 | K24: 83930 | L24: Fiber | M24: 43810 | N24: Yes | O24: =IF(N24="Yes",1,IF(N24="No",0,"")) -> 1 | P24: No | Q24: No | R24: No | S24: No | T24: No | U24: =IF(K24="","",K24+ROW()/1000000) -> 83930
A25: C1024 | B25: Payal Jain | C25: Female | D25: 28 | E25: =IF(D25<=25,"18-25",IF(D25<=35,"26-35",IF(D25<=45,"36-45",IF(D25<=60,"46-60","60+")))) -> 26-35 | F25: Unknown | G25: Two year | H25: 24 | I25: =IF(H25="","Unknown",IF(H25<=6,"0-6 months",IF(H25<=12,"7-12 months",IF(H25<=24,"13-24 months",IF(H25<=48,"25-48 months","49+ months"))))) -> 13-24 months | J25: 599 | K25: 14376 | L25: DSL | M25: 45201 | N25: No | O25: =IF(N25="Yes",1,IF(N25="No",0,"")) -> 0 | P25: No | Q25: No | R25: No | S25: No | T25: No | U25: =IF(K25="","",K25+ROW()/1000000) -> 14376
A26: C1025 | B26: Anjali Bose | C26: Female | D26: 33 | E26: =IF(D26<=25,"18-25",IF(D26<=35,"26-35",IF(D26<=45,"36-45",IF(D26<=60,"46-60","60+")))) -> 26-35 | F26: Lucknow | G26: One year | H26: 27 | I26: =IF(H26="","Unknown",IF(H26<=6,"0-6 months",IF(H26<=12,"7-12 months",IF(H26<=24,"13-24 months",IF(H26<=48,"25-48 months","49+ months"))))) -> 25-48 months | J26: 1149 | K26: 31023 | L26: Fiber | M26: 45089 | N26: No | O26: =IF(N26="Yes",1,IF(N26="No",0,"")) -> 0 | P26: No | Q26: No | R26: No | S26: No | T26: No | U26: =IF(K26="","",K26+ROW()/1000000) -> 31023
A27: C1026 | B27: Deepika Saxena | C27: Female | D27: 63 | E27: =IF(D27<=25,"18-25",IF(D27<=35,"26-35",IF(D27<=45,"36-45",IF(D27<=60,"46-60","60+")))) -> 60+ | F27: Pune | G27: Month-to-month | H27: 22 | I27: =IF(H27="","Unknown",IF(H27<=6,"0-6 months",IF(H27<=12,"7-12 months",IF(H27<=24,"13-24 months",IF(H27<=48,"25-48 months","49+ months"))))) -> 13-24 months | J27: 1049 | K27: 23078 | L27: Fiber | N27: Yes | O27: =IF(N27="Yes",1,IF(N27="No",0,"")) -> 1 | P27: No | Q27: No | R27: No | S27: No | T27: Date missing | U27: =IF(K27="","",K27+ROW()/1000000) -> 23078
A28: C1027 | B28: Rahul Kapoor | C28: Male | D28: 57 | E28: =IF(D28<=25,"18-25",IF(D28<=35,"26-35",IF(D28<=45,"36-45",IF(D28<=60,"46-60","60+")))) -> 46-60 | F28: Lucknow | G28: Two year | H28: 28 | I28: =IF(H28="","Unknown",IF(H28<=6,"0-6 months",IF(H28<=12,"7-12 months",IF(H28<=24,"13-24 months",IF(H28<=48,"25-48 months","49+ months"))))) -> 25-48 months | J28: 799 | K28: 22372 | L28: DSL | M28: 45060 | N28: No | O28: =IF(N28="Yes",1,IF(N28="No",0,"")) -> 0 | P28: No | Q28: No | R28: No | S28: No | T28: No | U28: =IF(K28="","",K28+ROW()/1000000) -> 22372
A29: C1028 | B29: Unknown | C29: Male | D29: 36 | E29: =IF(D29<=25,"18-25",IF(D29<=35,"26-35",IF(D29<=45,"36-45",IF(D29<=60,"46-60","60+")))) -> 36-45 | F29: Bangalore | G29: Month-to-month | H29: 10 | I29: =IF(H29="","Unknown",IF(H29<=6,"0-6 months",IF(H29<=12,"7-12 months",IF(H29<=24,"13-24 months",IF(H29<=48,"25-48 months","49+ months"))))) -> 7-12 months | J29: 1299 | K29: 12990 | L29: Fiber | M29: 45602 | N29: Yes | O29: =IF(N29="Yes",1,IF(N29="No",0,"")) -> 1 | P29: No | Q29: No | R29: No | S29: No | T29: No | U29: =IF(K29="","",K29+ROW()/1000000) -> 12990
A30: C1029 | B30: Anjali Singh | C30: Female | D30: 34 | E30: =IF(D30<=25,"18-25",IF(D30<=35,"26-35",IF(D30<=45,"36-45",IF(D30<=60,"46-60","60+")))) -> 26-35 | F30: Mumbai | G30: Two year | H30: 20 | I30: =IF(H30="","Unknown",IF(H30<=6,"0-6 months",IF(H30<=12,"7-12 months",IF(H30<=24,"13-24 months",IF(H30<=48,"25-48 months","49+ months"))))) -> 13-24 months | J30: 1049 | K30: 20980 | L30: Fiber | N30: No | O30: =IF(N30="Yes",1,IF(N30="No",0,"")) -> 0 | P30: No | Q30: Yes | R30: No | S30: No | T30: Date missing | U30: =IF(K30="","",K30+ROW()/1000000) -> 20980
A31: C1030 | B31: Suresh Jain | C31: Male | D31: 49 | E31: =IF(D31<=25,"18-25",IF(D31<=35,"26-35",IF(D31<=45,"36-45",IF(D31<=60,"46-60","60+")))) -> 46-60 | F31: Chennai | G31: Unknown | H31: 12 | I31: =IF(H31="","Unknown",IF(H31<=6,"0-6 months",IF(H31<=12,"7-12 months",IF(H31<=24,"13-24 months",IF(H31<=48,"25-48 months","49+ months"))))) -> 7-12 months | J31: 449 | K31: 5388 | L31: No Internet | M31: 45558 | N31: Yes | O31: =IF(N31="Yes",1,IF(N31="No",0,"")) -> 1 | P31: No | Q31: No | R31: No | S31: No | T31: No | U31: =IF(K31="","",K31+ROW()/1000000) -> 5388
A32: C1031 | B32: Suresh Gupta | C32: Male | D32: 65 | E32: =IF(D32<=25,"18-25",IF(D32<=35,"26-35",IF(D32<=45,"36-45",IF(D32<=60,"46-60","60+")))) -> 60+ | F32: Ahmedabad | G32: One year | H32: 1 | I32: =IF(H32="","Unknown",IF(H32<=6,"0-6 months",IF(H32<=12,"7-12 months",IF(H32<=24,"13-24 months",IF(H32<=48,"25-48 months","49+ months"))))) -> 0-6 months | J32: 899 | K32: 899 | L32: Fiber | M32: 45872 | N32: No | O32: =IF(N32="Yes",1,IF(N32="No",0,"")) -> 0 | P32: No | Q32: No | R32: No | S32: Yes | T32: No | U32: =IF(K32="","",K32+ROW()/1000000) -> 899.00003
A33: C1032 | B33: Tanvi Mishra | C33: Female | D33: 27 | E33: =IF(D33<=25,"18-25",IF(D33<=35,"26-35",IF(D33<=45,"36-45",IF(D33<=60,"46-60","60+")))) -> 26-35 | F33: Kolkata | G33: Month-to-month | H33: 2 | I33: =IF(H33="","Unknown",IF(H33<=6,"0-6 months",IF(H33<=12,"7-12 months",IF(H33<=24,"13-24 months",IF(H33<=48,"25-48 months","49+ months"))))) -> 0-6 months | J33: 699 | K33: 1398 | L33: DSL | M33: 45857 | N33: No | O33: =IF(N33="Yes",1,IF(N33="No",0,"")) -> 0 | P33: No | Q33: No | R33: No | S33: No | T33: No | U33: =IF(K33="","",K33+ROW()/1000000) -> 1398
A34: C1033 | B34: Riya Agarwal | C34: Female | D34: 27 | E34: =IF(D34<=25,"18-25",IF(D34<=35,"26-35",IF(D34<=45,"36-45",IF(D34<=60,"46-60","60+")))) -> 26-35 | F34: Hyderabad | G34: Two year | H34: 23 | I34: =IF(H34="","Unknown",IF(H34<=6,"0-6 months",IF(H34<=12,"7-12 months",IF(H34<=24,"13-24 months",IF(H34<=48,"25-48 months","49+ months"))))) -> 13-24 months | J34: 399 | K34: 9177 | L34: No Internet | M34: 45228 | N34: No | O34: =IF(N34="Yes",1,IF(N34="No",0,"")) -> 0 | P34: No | Q34: No | R34: No | S34: No | T34: No | U34: =IF(K34="","",K34+ROW()/1000000) -> 9177
A35: C1034 | B35: Ritu Malhotra | C35: Female | D35: 28 | E35: =IF(D35<=25,"18-25",IF(D35<=35,"26-35",IF(D35<=45,"36-45",IF(D35<=60,"46-60","60+")))) -> 26-35 | F35: Kochi | G35: One year | H35: 3 | I35: =IF(H35="","Unknown",IF(H35<=6,"0-6 months",IF(H35<=12,"7-12 months",IF(H35<=24,"13-24 months",IF(H35<=48,"25-48 months","49+ months"))))) -> 0-6 months | J35: 1099 | K35: 3297 | L35: Fiber | M35: 45809 | N35: Yes | O35: =IF(N35="Yes",1,IF(N35="No",0,"")) -> 1 | P35: No | Q35: No | R35: No | S35: No | T35: No | U35: =IF(K35="","",K35+ROW()/1000000) -> 3297
A36: C1035 | B36: Isha Iyer | C36: Female | D36: 70 | E36: =IF(D36<=25,"18-25",IF(D36<=35,"26-35",IF(D36<=45,"36-45",IF(D36<=60,"46-60","60+")))) -> 60+ | F36: Kochi | G36: Two year | H36: 25 | I36: =IF(H36="","Unknown",IF(H36<=6,"0-6 months",IF(H36<=12,"7-12 months",IF(H36<=24,"13-24 months",IF(H36<=48,"25-48 months","49+ months"))))) -> 25-48 months | J36: 749 | K36: 18725 | L36: DSL | M36: 45154 | N36: No | O36: =IF(N36="Yes",1,IF(N36="No",0,"")) -> 0 | P36: No | Q36: No | R36: No | S36: No | T36: No | U36: =IF(K36="","",K36+ROW()/1000000) -> 18725
A37: C1036 | B37: Isha Chopra | C37: Female | D37: 50 | E37: =IF(D37<=25,"18-25",IF(D37<=35,"26-35",IF(D37<=45,"36-45",IF(D37<=60,"46-60","60+")))) -> 46-60 | F37: Kolkata | G37: One year | H37: 22 | I37: =IF(H37="","Unknown",IF(H37<=6,"0-6 months",IF(H37<=12,"7-12 months",IF(H37<=24,"13-24 months",IF(H37<=48,"25-48 months","49+ months"))))) -> 13-24 months | J37: 449 | K37: 9878 | L37: No Internet | M37: 45260 | N37: No | O37: =IF(N37="Yes",1,IF(N37="No",0,"")) -> 0 | P37: No | Q37: No | R37: No | S37: No | T37: No | U37: =IF(K37="","",K37+ROW()/1000000) -> 9878
A38: C1037 | B38: Karan Yadav | C38: Male | D38: 45 | E38: =IF(D38<=25,"18-25",IF(D38<=35,"26-35",IF(D38<=45,"36-45",IF(D38<=60,"46-60","60+")))) -> 36-45 | F38: Pune | G38: One year | H38: 39 | I38: =IF(H38="","Unknown",IF(H38<=6,"0-6 months",IF(H38<=12,"7-12 months",IF(H38<=24,"13-24 months",IF(H38<=48,"25-48 months","49+ months"))))) -> 25-48 months | J38: 799 | K38: 31161 | L38: DSL | M38: 44752 | N38: No | O38: =IF(N38="Yes",1,IF(N38="No",0,"")) -> 0 | P38: No | Q38: No | R38: No | S38: No | T38: No | U38: =IF(K38="","",K38+ROW()/1000000) -> 31161
A39: C1038 | B39: Sneha Pandey | C39: Female | D39: 45 | E39: =IF(D39<=25,"18-25",IF(D39<=35,"26-35",IF(D39<=45,"36-45",IF(D39<=60,"46-60","60+")))) -> 36-45 | F39: Delhi | G39: Month-to-month | H39: 22 | I39: =IF(H39="","Unknown",IF(H39<=6,"0-6 months",IF(H39<=12,"7-12 months",IF(H39<=24,"13-24 months",IF(H39<=48,"25-48 months","49+ months"))))) -> 13-24 months | J39: 399 | K39: 8778 | L39: No Internet | M39: 45266 | N39: Yes | O39: =IF(N39="Yes",1,IF(N39="No",0,"")) -> 1 | P39: No | Q39: No | R39: Yes | S39: No | T39: No | U39: =IF(K39="","",K39+ROW()/1000000) -> 8778
A40: C1039 | B40: Riya Joshi | C40: Female | D40: 60 | E40: =IF(D40<=25,"18-25",IF(D40<=35,"26-35",IF(D40<=45,"36-45",IF(D40<=60,"46-60","60+")))) -> 46-60 | F40: Chandigarh | G40: Month-to-month | H40: 17 | I40: =IF(H40="","Unknown",IF(H40<=6,"0-6 months",IF(H40<=12,"7-12 months",IF(H40<=24,"13-24 months",IF(H40<=48,"25-48 months","49+ months"))))) -> 13-24 months | J40: 499 | K40: 8483 | L40: No Internet | M40: 45396 | N40: Yes | O40: =IF(N40="Yes",1,IF(N40="No",0,"")) -> 1 | P40: No | Q40: Yes | R40: No | S40: No | T40: No | U40: =IF(K40="","",K40+ROW()/1000000) -> 8483
...

Sheet analysis 
A1: Age group | B1: yes | C1: no | D1: churn rate | AE1: Monthly revenue lost | AF1: Formula
A2: 18-25 | B2: =COUNTIFS(Customer_churn_data!$E$2:$E$2001,$A2,Customer_churn_data!$N$2:$N$2001,"Yes") -> 85 | C2: =COUNTIFS(Customer_churn_data!$E$2:$E$2001,$A2,Customer_churn_data!$N$2:$N$2001,"No") -> 172 | D2: =B2/(B2+C2) -> 0.3307393 | F2: level 1: | H2: Here is an example for Q2 and Q5, in your own words:
A3: 26-35 | B3: =COUNTIFS(Customer_churn_data!$E$2:$E$2001,$A3,Customer_churn_data!$N$2:$N$2001,"Yes") -> 100 | C3: =COUNTIFS(Customer_churn_data!$E$2:$E$2001,$A3,Customer_churn_data!$N$2:$N$2001,"No") -> 230 | D3: =B3/(B3+C3) -> 0.3030303 | H3: "One in three customers is leaving, which is very high. Most of the churn (78%) comes from Month-to-month contracts, so the retention effort should target them first."
A4: 36-45 | B4: =COUNTIFS(Customer_churn_data!$E$2:$E$2001,$A4,Customer_churn_data!$N$2:$N$2001,"Yes") -> 121 | C4: =COUNTIFS(Customer_churn_data!$E$2:$E$2001,$A4,Customer_churn_data!$N$2:$N$2001,"No") -> 204 | D4: =B4/(B4+C4) -> 0.37230769 | G4: 1. How many unique customers are in the dataset?
A5: 46-60 | B5: =COUNTIFS(Customer_churn_data!$E$2:$E$2001,$A5,Customer_churn_data!$N$2:$N$2001,"Yes") -> 188 | C5: =COUNTIFS(Customer_churn_data!$E$2:$E$2001,$A5,Customer_churn_data!$N$2:$N$2001,"No") -> 379 | D5: =B5/(B5+C5) -> 0.33156966 | G5: 2. How many customers have churned, and what is the overall churn rate (%)? Exclude customers whose churn status is "Unknown" from the calculation.
A6: 60+ | B6: =COUNTIFS(Customer_churn_data!$E$2:$E$2001,$A6,Customer_churn_data!$N$2:$N$2001,"Yes") -> 171 | C6: =COUNTIFS(Customer_churn_data!$E$2:$E$2001,$A6,Customer_churn_data!$N$2:$N$2001,"No") -> 315 | D6: =B6/(B6+C6) -> 0.35185185 | G6: 3. What is the average Monthly Charges across all customers?
G7: 4. What is the total revenue (sum of Total Charges) across all customers?
G8: 5. How many customers are on a Month-to-month contract and have churned?
K10: insight:
F11: solutions : | H11: 1 | I11: =COUNTA(Customer_churn_data!$A$2:$A$2001) -> 2000 | K11: Insight: "The cleaned base has 2,000 unique customers, after removing 50 duplicates and 8 blank rows."
H12: 2 | I12: =COUNTIF(Customer_churn_data!$N$2:$N$2001,"Yes") -> 665 | J12: =COUNTIF(Customer_churn_data!$N$2:$N$2001,"Yes")/(COUNTIF(Customer_churn_data!$N$2:$N$2001,"Yes")+COUNTIF(Customer_churn_data!$N$2:$N$2001,"No")) -> 0.33842239 | K12: Insight: "One in three customers has left. That is very high and needs urgent action."
H13: 3 | I13: =AVERAGE(Customer_churn_data!$J$2:$J$2001) -> 847.00404 | K13: Insight: "The average customer pays about ₹847 a month. This is the baseline to price retention offers against."
H14: 4 | I14: =SUM(Customer_churn_data!$K$2:$K$2001) -> 32017927 | K14: . Insight: "About ₹3.2 crore of lifetime billing sits in this customer base, so losing a third of customers is a serious revenue risk." Note: 17 Total Charges cells are blank, so the real figure is slightly higher.
H15: 5 | I15: =COUNTIFS(Customer_churn_data!$G$2:$G$2001,"Month-to-month",Customer_churn_data!$N$2:$N$2001,"Yes") -> 516 | K15: Insight: "516 of 665 churned customers (78%) were on Month-to-month plans, so contract type is the main churn driver."
F17: level 2: | G17: pivot tables
G18: 6. What is the churn rate for each Contract Type? Which contract is the riskiest? (You've already done this one ✅)
G19: 7. What is the churn rate for each Internet Service type (DSL, Fiber, No Internet)? Which service has the highest churn?
G20: 8. City-wise analysis: For each city, show the number of customers, total revenue (Total Charges) and churn rate. Which are the top 3 and bottom 3 cities by churn rate?
G21: 9. Tenure buckets: Create buckets (0-6, 7-12, 13-24, 25-48, 49+ months). Which bucket has the highest churn rate?
G22: 10. Age groups: Create groups (18-25, 26-35, 36-45, 46-60, 60+). Which age group churns the most?
F24: level 3:
G26: Q11. Monthly revenue lost from churned customers
G27: Q12. Annual revenue at risk
G28: Q13. Retention scenario (reduce Month-to-month churn by 10 points)
G29: Q14. Top 10 customers by Total Charges
G30: Q15. Customer lookup box
G31: Q16. City churn rate table with population
L33: insights:
F34: solutions:
G35: 11 | H35: =SUMIFS(Customer_churn_data!$J$2:$J$2001,Customer_churn_data!$N$2:$N$2001,"Yes") -> 567095 | L35: Insight: "Churned customers represented about 34% of total monthly billing. Almost a third of recurring revenue has walked out." Note: 10 churned customers have a blank Monthly Charge, so this is slightly understated.
G36: 12 | H36: monthly revenue at risk | J36: =SUMIFS(Customer_churn_data!$J$2:$J$2001,Customer_churn_data!$N$2:$N$2001,"Yes") -> 567095 | L36: Insight: About a third of the company's monthly billing is lost to churn, so even a small improvement in retention is worth lakhs.
H37: annual revenue at risk | J37: =J36*12 -> 6805140
G38: 13 | H38: churn reduction (assumption) | J38: 0.1 | O38: Insight: "Cutting Month-to-month churn from 47.8% to 37.8% would save about 108 customers and around ₹11 lakh a year. Month-to-month customers also account for about 77% of the monthly revenue lost, so this is the best place to spend retention budget." Change B1 to 5% or 15% and the answer updates automatically, which is a good thing to show in an interview.
H39: moth to month customers with known churn status | M39: =COUNTIFS(Customer_churn_data!$G$2:$G$2001,"Month-to-month",Customer_churn_data!$N$2:$N$2001,"Yes")+COUNTIFS(Customer_churn_data!$G$2:$G$2001,"Month-to-month",Customer_churn_data!$N$2:$N$2001,"No") -> 1080
H40: avg monthly charge of churned month to month | M40: =AVERAGEIFS(Customer_churn_data!$J$2:$J$2001,Customer_churn_data!$G$2:$G$2001,"Month-to-month",Customer_churn_data!$N$2:$N$2001,"Yes") -> 857.85827
H41: Customer saved | I41: 108
H42: Monthly revenue saved | I42: =M39*M40 -> 926486.93
B43: 14. solution-> | H43: Annual revenue saved | I43: =I42*12 -> 11117843
B44: rank | C44: Totalkey | D44: CustID | E44: Total Charges | F44: Churn
B45: 1 | C45: =LARGE(Customer_churn_data!$U$2:$U$2001,B45) -> 89631.001 | D45: =INDEX(Customer_churn_data!$A$2:$A$2001,MATCH(C45,Customer_churn_data!$U$2:$U$2001,0)) -> C1528 | E45: =INDEX(Customer_churn_data!$K$2:$K$2001,MATCH(C45,Customer_churn_data!$U$2:$U$2001,0)) -> 89631 | F45: =INDEX(Customer_churn_data!$N$2:$N$2001,MATCH(C45,Customer_churn_data!$U$2:$U$2001,0)) -> No
...

Sheet Pivot tables 
A2: Row Labels | B2: Count of CustID
A3: Month-to-month | B3: 1097
A4: One year | B4: 501
A5: Two year | B5: 375
A6: Unknown | B6: 27
A7: (blank)
A8: Grand Total | B8: 2000
A18: 6. Insight: Month-to-month customers churn more than 4x as often as two-year customers. Contract length is the strongest churn driver in this data.
A19: Action: Offer discounts or perks to move month-to-month customers onto one-year plans.
A21: Count of CustID | B21: Column Labels
A22: Row Labels | B22: No | C22: Unknown | D22: Yes | E22: Grand Total
A23: DSL | B23: 488 | C23: 13 | D23: 196 | E23: 697
A24: Fiber | B24: 541 | C24: 16 | D24: 328 | E24: 885
A25: No Internet | B25: 240 | C25: 6 | D25: 130 | E25: 376
A26: Unknown | B26: 31 | D26: 11 | E26: 42
A27: Grand Total | B27: 1300 | C27: 35 | D27: 665 | E27: 2000
A28: 7. Insight: Fiber customers pay the most but churn the most, about 9 points above DSL. That is the costliest kind of churn. The "No Internet" group also churns at a high rate, which suggests those customers get little value from the plan.
A29: Action: Investigate Fiber service quality and pricing. Consider bundling offers for No Internet customers.
A31: Row Labels | B31: Count of CustID
A32: Ahmedabad | B32: 147
A33: Bangalore | B33: 143
A34: Bhopal | B34: 123
A35: Chandigarh | B35: 139
A36: Chennai | B36: 129
A37: Delhi | B37: 149
A38: Hyderabad | B38: 136
A39: Indore | B39: 138
A40: Jaipur | B40: 141
A41: Kochi | B41: 154
A42: Kolkata | B42: 139
A43: Lucknow | B43: 143
... A47: Grand Total | B47: 2000
A48: 8. Insight: City matters much less than contract type. The gap between best and worst city is about 9 points, and each city has only about 125 to 150 customers, so part of that gap is likely random variation.
A49: Action: Don't launch city-specific campaigns based on this alone. Use contract and tenure to target customers instead, and treat city as a secondary filter. Revenue per city is fairly even (₹19 to 25 lakh), so no single city dominates.
A51: Count of CustID | B51: Column Labels
A52: Row Labels | B52: No | C52: Unknown | D52: Yes | E52: Grand Total
A53: DSL | B53: 0.70014347 | C53: 0.018651363 | D53: 0.28120516 | E53: 1
A54: Fiber | B54: 0.61129944 | C54: 0.018079096 | D54: 0.37062147 | E54: 1
A55: No Internet | B55: 0.63829787 | C55: 0.015957447 | D55: 0.34574468 | E55: 1
A56: Unknown | B56: 0.73809524 | C56: 0 | D56: 0.26190476 | E56: 1
...

Sheet dashboard
B1: Customer Churn Dashboard
B3: Telecom subscription base · 2,000 unique customers · churn rate = Yes ÷ (Yes + No), unknown status excluded
B5: TOTAL CUSTOMERS | G5: CHURN RATE | L5: MONTHLY REVENUE LOST | Q5: ANNUAL REVENUE AT RISK
B6: =[1]Calc!B2 -> 2000 | G6: =[1]Calc!B4 -> 0.33842239 | L6: =[1]Calc!B5 -> 567095 | Q6: =[1]Calc!B6 -> 6805140
B36: KEY INSIGHTS
B37: 1. Contract type is the strongest driver: Month-to-month churn is 47.8% vs 10.9% for Two-year customers.
B38: 2. The first 6 months are critical: 49.7% churn, falling to 8.6% after 4 years. Focus on onboarding and early retention.
B39: 3. Fiber (37.7%) churns more than DSL (28.7%). Review Fiber service quality and pricing.
B40: 4. City and age matter far less (about 29% to 38% across cities, 30% to 37% across ages). Do not target by them.
B41: 5. About ₹68 lakh a year is at risk. Cutting Month-to-month churn by 10 points could save about ₹11 lakh a year.

Sheet analysis of problem with sol.
A1: problem :
A2: i want all detail about this file through buisness insights explain the main points of this data and how can i explain my data tell me every thing mujh proffes
A4: solution:
C5: Check in with new customers: Contact them during their first few months to make sure setup and service are working well.
C6: Resolve problems quickly: Give prompt, proactive support to customers who report service issues or make repeated complaints.
C7: Offer a reason to stay: Provide a reasonable discount or an extra benefit to month-to-month customers who choose an annual plan.
C8: Ask customers for feedback: Find out whether price, service quality, or customer support influenced their decision to leave.
C9: Track churn each month: Measure whether these steps help more customers stay.
C10: Collect more information: The current data shows which customers are more likely to leave, but not why. Customer feedback can help identify the causes.
B13: Additional Business Problems and Recommended Solutions
A15: 1 | B15: High churn among early-tenure customers: Customers in their first six months have a 49.7% churn rate.
B16: Solution: Strengthen onboarding, check in with customers during the first few months, and resolve setup or service issues quickly.
A18: 2 | B18: Higher churn among fiber customers: Fiber customers have a 37.7% churn rate, compared with 28.7% for DSL customers.
B19: Solution: Review fiber customers’ service quality, pricing, and complaint history to identify possible issues before choosing a retention action.
A21: 3 | B21: Churn is concentrated in month-to-month plans: These customers make up 77.6% of known churned customers and account for about 76.8% of the monthly charges linked to churned accounts.
B22: Solution: Offer suitable plan options or benefits to encourage customers to stay, and track whether the offers are cost-effective.
A24: 4 | B24: Some customer information is missing or estimated: The file contains unknown churn statuses and values marked as imputed.
B25: Solution: Improve data collection and validation, and clearly flag estimated values when reporting results.
A27: 5 | B27: The reasons and timing of churn are not recorded: The workbook shows which customers left, but not when they left or why.
B28: Solution: Record cancellation dates and reasons, then review churn by month and customer group.
A30: 6 | B30: Churn rates differ across cities: For example, Chennai’s rate is 38.1%, while Kolkata’s is 28.8%.
B31: Solution: Investigate local service or customer-support issues, while treating these figures as signals to explore rather than confirmed causes.
A33: 7 | B33: Price may be worth investigating: Churned customers’ average monthly charge is slightly higher than retained customers’. This does not prove that price caused churn.
B34: Solution: Ask customers about price and perceived value, then test any pricing changes with a small customer group.
B36: Note: These findings highlight areas for investigation. The workbook does not establish the causes of churn, so customer feedback and service data are needed before deciding on specific changes.
A40: ABOUT THIS PROJECT:
C42: "I analysed a telecom subscription business that was losing one in three customers, which put about ₹68 lakh a year in revenue at risk.
C43: I cleaned a messy dataset of 2,000 customers, analysed it in Excel using formulas and pivot tables, and built a dashboard
C44: I found that churn is driven mainly by contract type and early tenure: Month-to-month customers churn at 47.8% compared with 10.9% for two-year customers, and nearly half of new customers leave within six months.
C45: My recommendation is to move customers onto longer contracts and strengthen onboarding, which could save roughly ₹11 lakh a year."
B47: 1. Business problem
B49: "The company's churn rate is 33.8%.Put differently, it loses about ₹5.7 lakh in monthly billing, or roughly₹68 lakh a year, to customers who leave.
B50: The question I set out to answer was: who is leaving, why, and what can the business do about it?"
B52: 2. Data and approach
B54: "The raw file had 2,058 rows with serious quality issues: 50 duplicate customers, blank rows, mixed date formats, prices stored as text, impossible ages and tenures, and inconsistent labels like 'Dehli' and 'Bengaluru'.
B55: I cleaned it down to 2,000 unique customers and documented every fix in an issues log. Where values were missing,
B56: I rebuilt them from related fields when possible, for example Total Charges equals Monthly Charges times Tenure, and I did not guess the churn status itself."
B58: 3. Key findings
B60: "First, contract type is the strongest driver. Month-to-month customers churn at 47.8%, versus 20.2% for one-year and 10.9% for two-year contracts.
B61: They also make up 78% of all churned customers.
...

Sheet calculations
A1: KPIs
A2: Total customers | B2: =COUNTA([1]Data!$A$2:$A$2001) -> 2000
A3: Churned customers | B3: =COUNTIF([1]Data!$L$2:$L$2001,"Yes") -> 665
A4: Churn rate | B4: =B3/(B3+COUNTIF([1]Data!$L$2:$L$2001,"No")) -> 0.33842239
A5: Monthly revenue lost | B5: =SUMIFS([1]Data!$H$2:$H$2001,[1]Data!$L$2:$L$2001,"Yes") -> 567095
A6: Annual revenue at risk | B6: =B5*12 -> 6805140
A7: Contract Type
A8: Group | B8: Yes | C8: No | D8: Churn rate | E8: Overall avg
A9: Month-to-month | B9: =COUNTIFS([1]Data!$F$2:$F$2001,$A9,[1]Data!$L$2:$L$2001,"Yes") -> 516 | C9: =COUNTIFS([1]Data!$F$2:$F$2001,$A9,[1]Data!$L$2:$L$2001,"No") -> 564 | D9: =B9/(B9+C9) -> 0.47777778 | E9: =$B$4 -> 0.33842239
A10: One year | B10: =COUNTIFS([1]Data!$F$2:$F$2001,$A10,[1]Data!$L$2:$L$2001,"Yes") -> 99 | C10: =COUNTIFS([1]Data!$F$2:$F$2001,$A10,[1]Data!$L$2:$L$2001,"No") -> 392 | D10: =B10/(B10+C10) -> 0.20162933 | E10: =$B$4 -> 0.33842239
A11: Two year | B11: =COUNTIFS([1]Data!$F$2:$F$2001,$A11,[1]Data!$L$2:$L$2001,"Yes") -> 40 | C11: =COUNTIFS([1]Data!$F$2:$F$2001,$A11,[1]Data!$L$2:$L$2001,"No") -> 328 | D11: =B11/(B11+C11) -> 0.10869565 | E11: =$B$4 -> 0.33842239
A14: Internet Service
A15: Group | B15: Yes | C15: No | D15: Churn rate | E15: Overall avg
A16: DSL | B16: =COUNTIFS([1]Data!$J$2:$J$2001,$A16,[1]Data!$L$2:$L$2001,"Yes") -> 196 | C16: =COUNTIFS([1]Data!$J$2:$J$2001,$A16,[1]Data!$L$2:$L$2001,"No") -> 488 | D16: =B16/(B16+C16) -> 0.28654971 | E16: =$B$4 -> 0.33842239
A17: Fiber | B17: =COUNTIFS([1]Data!$J$2:$J$2001,$A17,[1]Data!$L$2:$L$2001,"Yes") -> 328 | C17: =COUNTIFS([1]Data!$J$2:$J$2001,$A17,[1]Data!$L$2:$L$2001,"No") -> 541 | D17: =B17/(B17+C17) -> 0.37744534 | E17: =$B$4 -> 0.33842239
A18: No Internet | B18: =COUNTIFS([1]Data!$J$2:$J$2001,$A18,[1]Data!$L$2:$L$2001,"Yes") -> 130 | C18: =COUNTIFS([1]Data!$J$2:$J$2001,$A18,[1]Data!$L$2:$L$2001,"No") -> 240 | D18: =B18/(B18+C18) -> 0.35135135 | E18: =$B$4 -> 0.33842239
A21: City
A22: Group | B22: Yes | C22: No | D22: Churn rate | E22: Overall avg
A23: Chennai | B23: =COUNTIFS([1]Data!$E$2:$E$2001,$A23,[1]Data!$L$2:$L$2001,"Yes") -> 48 | C23: =COUNTIFS([1]Data!$E$2:$E$2001,$A23,[1]Data!$L$2:$L$2001,"No") -> 78 | D23: =B23/(B23+C23) -> 0.38095238 | E23: =$B$4 -> 0.33842239
A24: Indore | B24: =COUNTIFS([1]Data!$E$2:$E$2001,$A24,[1]Data!$L$2:$L$2001,"Yes") -> 51 | C24: =COUNTIFS([1]Data!$E$2:$E$2001,$A24,[1]Data!$L$2:$L$2001,"No") -> 86 | D24: =B24/(B24+C24) -> 0.37226277 | E24: =$B$4 -> 0.33842239
A25: Chandigarh | B25: =COUNTIFS([1]Data!$E$2:$E$2001,$A25,[1]Data!$L$2:$L$2001,"Yes") -> 50 | C25: =COUNTIFS([1]Data!$E$2:$E$2001,$A25,[1]Data!$L$2:$L$2001,"No") -> 87 | D25: =B25/(B25+C25) -> 0.3649635 | E25: =$B$4 -> 0.33842239
A26: Mumbai | B26: =COUNTIFS([1]Data!$E$2:$E$2001,$A26,[1]Data!$L$2:$L$2001,"Yes") -> 47 | C26: =COUNTIFS([1]Data!$E$2:$E$2001,$A26,[1]Data!$L$2:$L$2001,"No") -> 82 | D26: =B26/(B26+C26) -> 0.36434109 | E26: =$B$4 -> 0.33842239
A27: Lucknow | B27: =COUNTIFS([1]Data!$E$2:$E$2001,$A27,[1]Data!$L$2:$L$2001,"Yes") -> 50 | C27: =COUNTIFS([1]Data!$E$2:$E$2001,$A27,[1]Data!$L$2:$L$2001,"No") -> 91 | D27: =B27/(B27+C27) -> 0.35460993 | E27: =$B$4 -> 0.33842239
A28: Delhi | B28: =COUNTIFS([1]Data!$E$2:$E$2001,$A28,[1]Data!$L$2:$L$2001,"Yes") -> 51 | C28: =COUNTIFS([1]Data!$E$2:$E$2001,$A28,[1]Data!$L$2:$L$2001,"No") -> 93 | D28: =B28/(B28+C28) -> 0.35416667 | E28: =$B$4 -> 0.33842239
A29: Jaipur | B29: =COUNTIFS([1]Data!$E$2:$E$2001,$A29,[1]Data!$L$2:$L$2001,"Yes") -> 48 | C29: =COUNTIFS([1]Data!$E$2:$E$2001,$A29,[1]Data!$L$2:$L$2001,"No") -> 90 | D29: =B29/(B29+C29) -> 0.34782609 | E29: =$B$4 -> 0.33842239
A30: Hyderabad | B30: =COUNTIFS([1]Data!$E$2:$E$2001,$A30,[1]Data!$L$2:$L$2001,"Yes") -> 46 | C30: =COUNTIFS([1]Data!$E$2:$E$2001,$A30,[1]Data!$L$2:$L$2001,"No") -> 88 | D30: =B30/(B30+C30) -> 0.34328358 | E30: =$B$4 -> 0.33842239
A31: Kochi | B31: =COUNTIFS([1]Data!$E$2:$E$2001,$A31,[1]Data!$L$2:$L$2001,"Yes") -> 51 | C31: =COUNTIFS([1]Data!$E$2:$E$2001,$A31,[1]Data!$L$2:$L$2001,"No") -> 98 | D31: =B31/(B31+C31) -> 0.34228188 | E31: =$B$4 -> 0.33842239
A32: Bhopal | B32: =COUNTIFS([1]Data!$E$2:$E$2001,$A32,[1]Data!$L$2:$L$2001,"Yes") -> 42 | C32: =COUNTIFS([1]Data!$E$2:$E$2001,$A32,[1]Data!$L$2:$L$2001,"No") -> 81 | D32: =B32/(B32+C32) -> 0.34146341 | E32: =$B$4 -> 0.33842239
A33: Pune | B33: =COUNTIFS([1]Data!$E$2:$E$2001,$A33,[1]Data!$L$2:$L$2001,"Yes") -> 44 | C33: =COUNTIFS([1]Data!$E$2:$E$2001,$A33,[1]Data!$L$2:$L$2001,"No") -> 96 | D33: =B33/(B33+C33) -> 0.31428571 | E33: =$B$4 -> 0.33842239
A34: Ahmedabad | B34: =COUNTIFS([1]Data!$E$2:$E$2001,$A34,[1]Data!$L$2:$L$2001,"Yes") -> 43 | C34: =COUNTIFS([1]Data!$E$2:$E$2001,$A34,[1]Data!$L$2:$L$2001,"No") -> 103 | D34: =B34/(B34+C34) -> 0.29452055 | E34: =$B$4 -> 0.33842239
... A36: Kolkata | B36: =COUNTIFS([1]Data!$E$2:$E$2001,$A36,[1]Data!$L$2:$L$2001,"Yes") -> 40 | C36: =COUNTIFS([1]Data!$E$2:$E$2001,$A36,[1]Data!$L$2:$L$2001,"No") -> 99 | D36: =B36/(B36+C36) -> 0.28776978 | E36: =$B$4 -> 0.33842239
A39: Tenure
A40: Group | B40: Yes | C40: No | D40: Churn rate | E40: Overall avg
A41: 0-6 mo | B41: =COUNTIFS([1]Data!$M$2:$M$2001,$A41,[1]Data!$L$2:$L$2001,"Yes") -> 184 | C41: =COUNTIFS([1]Data!$M$2:$M$2001,$A41,[1]Data!$L$2:$L$2001,"No") -> 186 | D41: =B41/(B41+C41) -> 0.4972973 | E41: =$B$4 -> 0.33842239
A42: 7-12 mo | B42: =COUNTIFS([1]Data!$M$2:$M$2001,$A42,[1]Data!$L$2:$L$2001,"Yes") -> 153 | C42: =COUNTIFS([1]Data!$M$2:$M$2001,$A42,[1]Data!$L$2:$L$2001,"No") -> 248 | D42: =B42/(B42+C42) -> 0.38154613 | E42: =$B$4 -> 0.33842239
A43: 13-24 mo | B43: =COUNTIFS([1]Data!$M$2:$M$2001,$A43,[1]Data!$L$2:$L$2001,"Yes") -> 261 | C43: =COUNTIFS([1]Data!$M$2:$M$2001,$A43,[1]Data!$L$2:$L$2001,"No") -> 485 | D43: =B43/(B43+C43) -> 0.34986595 | E43: =$B$4 -> 0.33842239
A44: 25-48 mo | B44: =COUNTIFS([1]Data!$M$2:$M$2001,$A44,[1]Data!$L$2:$L$2001,"Yes") -> 48 | C44: =COUNTIFS([1]Data!$M$2:$M$2001,$A44,[1]Data!$L$2:$L$2001,"No") -> 242 | D44: =B44/(B44+C44) -> 0.16551724 | E44: =$B$4 -> 0.33842239
A45: 49+ mo | B45: =COUNTIFS([1]Data!$M$2:$M$2001,$A45,[1]Data!$L$2:$L$2001,"Yes") -> 12 | C45: =COUNTIFS([1]Data!$M$2:$M$2001,$A45,[1]Data!$L$2:$L$2001,"No") -> 128 | D45: =B45/(B45+C45) -> 0.085714286 | E45: =$B$4 -> 0.33842239
A48: Age Group
A49: Group | B49: Yes | C49: No | D49: Churn rate | E49: Overall avg
...
